Workbook

Sheet Financial Statements
A1: FINANCIAL STATEMENTS
A2: ='Transaction Analysis'!$B$2 -> Company Name
A3: ="For the period ended "&TEXT('Transaction Analysis'!$B$3,"mmmm d, yyyy") -> For the period ended December 31, 2027
A5: Income Statement | H5: Statement of Retained Earnings
A6: ="For the period ended "&TEXT('Transaction Analysis'!$B$3,"mmmm d, yyyy") -> For the period ended December 31, 2027 | H6: ="For the period ended "&TEXT('Transaction Analysis'!$B$3,"mmmm d, yyyy") -> For the period ended December 31, 2027
A8: Revenues
A9: Service revenue | E9: =SUM('Transaction Analysis'!$L$7:$L$1006) -> 0 | H9: Beginning retained earnings | M9: ='Transaction Analysis'!$B$4 -> 0
A10: Other revenue | E10: =SUM('Transaction Analysis'!$M$7:$M$1006) -> 0 | H10: Add: Net income | M10: =E18 -> 0
A11: Total revenues | E11: =SUM(E9:E10) -> 0 | H11: Less: Dividends | M11: =SUM('Transaction Analysis'!$K$7:$K$1006) -> 0
A12: Expenses
A13: Rent expense | E13: =SUM('Transaction Analysis'!$N$7:$N$1006) -> 0 | H13: Ending retained earnings | M13: =M9+M10-M11 -> 0
A14: Salaries expense | E14: =SUM('Transaction Analysis'!$O$7:$O$1006) -> 0
A15: Utilities expense | E15: =SUM('Transaction Analysis'!$P$7:$P$1006) -> 0
A16: Other expense | E16: =SUM('Transaction Analysis'!$Q$7:$Q$1006) -> 0
A17: Total expenses | E17: =SUM(E13:E16) -> 0
A18: Net income | E18: =E11-E17 -> 0
A22: Balance Sheet
A23: =TEXT('Transaction Analysis'!$B$3,"mmmm d, yyyy") -> December 31, 2027
A25: Assets | H25: Liabilities
A26: Cash | E26: ='Transaction Analysis'!$E$2+SUM('Transaction Analysis'!$C$7:$C$1006) -> 0 | H26: Accounts payable | M26: =SUM('Transaction Analysis'!$H$7:$H$1006) -> 0
A27: Accounts receivable | E27: =SUM('Transaction Analysis'!$D$7:$D$1006) -> 0 | H27: Notes payable | M27: =SUM('Transaction Analysis'!$I$7:$I$1006) -> 0
A28: Supplies | E28: =SUM('Transaction Analysis'!$E$7:$E$1006) -> 0 | H28: Total liabilities | M28: =SUM(M26:M27) -> 0
A29: Prepaid expenses | E29: =SUM('Transaction Analysis'!$F$7:$F$1006) -> 0
A30: Equipment | E30: =SUM('Transaction Analysis'!$G$7:$G$1006) -> 0 | H30: Equity
A31: Total assets | E31: =SUM(E26:E30) -> 0 | H31: Common stock | M31: =SUM('Transaction Analysis'!$J$7:$J$1006) -> 0
H32: Retained earnings | M32: =M13 -> 0
H33: Total equity | M33: =SUM(M31:M32) -> 0
H35: Total liabilities and equity | M35: =M28+M33 -> 0
A40: Statement of Cash Flows | H40: Return on Assets
A41: ="For the period ended "&TEXT('Transaction Analysis'!$B$3,"mmmm d, yyyy") -> For the period ended December 31, 2027
H42: Net income | M42: =E18 -> 0
A43: Cash flows from operating activities | H43: Beginning total assets | M43: ='Transaction Analysis'!$E$3 -> 0
A44: Net cash provided by operating activities | E44: =SUM('Transaction Analysis'!$R$7:$R$1006) -> 0 | H44: Ending total assets | M44: =E31 -> 0
H45: Average total assets | M45: =AVERAGE(M43:M44) -> 0
A46: Cash flows from investing activities | H46: Return on assets | M46: =IF(M45=0,"n.a.",M42/M45) -> n.a.
A47: Net cash provided by investing activities | E47: =SUM('Transaction Analysis'!$S$7:$S$1006) -> 0
A49: Cash flows from financing activities
A50: Net cash provided by financing activities | E50: =SUM('Transaction Analysis'!$T$7:$T$1006) -> 0 | H50: Reconciliation Checks
A52: Net increase (decrease) in cash | E52: =SUM(E44,E47,E50) -> 0 | H52: Net income tie | M52: =E18-(E11-E17) -> 0
A53: Beginning cash balance | E53: ='Transaction Analysis'!$E$2 -> 0 | H53: Ending retained earnings tie | M53: =M13-M32 -> 0
...

Sheet Transaction Analysis
A1: EXPANDED ACCOUNTING EQUATION / TRANSACTION ANALYSIS
A2: Company name | B2: Company Name | D2: Beginning cash | E2: 0 | G2: Entry rules
A3: Period end | B3: 46752 | D3: Beginning assets | E3: 0 | G3: Positive = increase | J3: Cash paid = negative | M3: Dividends/expenses = positive | Q3: Classify cash in one CFO/CFI/CFF column | U3: Disclose noncash items
A4: Beginning retained earnings | B4: 0 | D4: Currency | E4: USD | G4: Enter one transaction per row. | J4: Each row must balance. | M4: Checks should equal zero. | Q4: Unused rows may stay blank.
A5: Transaction | C5: Assets | H5: Liabilities | J5: Equity | R5: Cash Flow Classification | U5: Disclosure | V5: Row Checks
A6: Date | B6: Description | C6: Cash | D6: Accounts Receivable | E6: Supplies | F6: Prepaid Expenses | G6: Equipment | H6: Accounts Payable | I6: Notes Payable | J6: Common Stock | K6: Dividends | L6: Service Revenue | M6: Other Revenue | N6: Rent Expense | O6: Salaries Expense | P6: Utilities Expense | Q6: Other Expense | R6: Operating Cash Flow | S6: Investing Cash Flow | T6: Financing Cash Flow | U6: Noncash Disclosure | V6: Equation Check | W6: Cash Classification Check
V7: =IF(COUNTA($A7:$U7)=0,"",SUM($C7:$G7)-SUM($H7:$I7)-$J7+$K7-$L7-$M7+SUM($N7:$Q7)) | W7: =IF(COUNTA($A7:$U7)=0,"",$C7-SUM($R7:$T7))
V8: =IF(COUNTA($A8:$U8)=0,"",SUM($C8:$G8)-SUM($H8:$I8)-$J8+$K8-$L8-$M8+SUM($N8:$Q8)) | W8: =IF(COUNTA($A8:$U8)=0,"",$C8-SUM($R8:$T8))
V9: =IF(COUNTA($A9:$U9)=0,"",SUM($C9:$G9)-SUM($H9:$I9)-$J9+$K9-$L9-$M9+SUM($N9:$Q9)) | W9: =IF(COUNTA($A9:$U9)=0,"",$C9-SUM($R9:$T9))
V10: =IF(COUNTA($A10:$U10)=0,"",SUM($C10:$G10)-SUM($H10:$I10)-$J10+$K10-$L10-$M10+SUM($N10:$Q10)) | W10: =IF(COUNTA($A10:$U10)=0,"",$C10-SUM($R10:$T10))
V11: =IF(COUNTA($A11:$U11)=0,"",SUM($C11:$G11)-SUM($H11:$I11)-$J11+$K11-$L11-$M11+SUM($N11:$Q11)) | W11: =IF(COUNTA($A11:$U11)=0,"",$C11-SUM($R11:$T11))
V12: =IF(COUNTA($A12:$U12)=0,"",SUM($C12:$G12)-SUM($H12:$I12)-$J12+$K12-$L12-$M12+SUM($N12:$Q12)) | W12: =IF(COUNTA($A12:$U12)=0,"",$C12-SUM($R12:$T12))
V13: =IF(COUNTA($A13:$U13)=0,"",SUM($C13:$G13)-SUM($H13:$I13)-$J13+$K13-$L13-$M13+SUM($N13:$Q13)) | W13: =IF(COUNTA($A13:$U13)=0,"",$C13-SUM($R13:$T13))
V14: =IF(COUNTA($A14:$U14)=0,"",SUM($C14:$G14)-SUM($H14:$I14)-$J14+$K14-$L14-$M14+SUM($N14:$Q14)) | W14: =IF(COUNTA($A14:$U14)=0,"",$C14-SUM($R14:$T14))
V15: =IF(COUNTA($A15:$U15)=0,"",SUM($C15:$G15)-SUM($H15:$I15)-$J15+$K15-$L15-$M15+SUM($N15:$Q15)) | W15: =IF(COUNTA($A15:$U15)=0,"",$C15-SUM($R15:$T15))
V16: =IF(COUNTA($A16:$U16)=0,"",SUM($C16:$G16)-SUM($H16:$I16)-$J16+$K16-$L16-$M16+SUM($N16:$Q16)) | W16: =IF(COUNTA($A16:$U16)=0,"",$C16-SUM($R16:$T16))
V17: =IF(COUNTA($A17:$U17)=0,"",SUM($C17:$G17)-SUM($H17:$I17)-$J17+$K17-$L17-$M17+SUM($N17:$Q17)) | W17: =IF(COUNTA($A17:$U17)=0,"",$C17-SUM($R17:$T17))
V18: =IF(COUNTA($A18:$U18)=0,"",SUM($C18:$G18)-SUM($H18:$I18)-$J18+$K18-$L18-$M18+SUM($N18:$Q18)) | W18: =IF(COUNTA($A18:$U18)=0,"",$C18-SUM($R18:$T18))
... V1006: =IF(COUNTA($A1006:$U1006)=0,"",SUM($C1006:$G1006)-SUM($H1006:$I1006)-$J1006+$K1006-$L1006-$M1006+SUM($N1006:$Q1006)) | W1006: =IF(COUNTA($A1006:$U1006)=0,"",$C1006-SUM($R1006:$T1006))
